Workbook

Sheet Product Backlog
A1: PRODUCT BACKLOG – Sistema de gestión de inventarios – Empresa Luany
A2: Product Owner: Dayana De la Cruz Pachas | Ordenado de mayor a menor prioridad. Los puntos de historia son una estimación inicial (escala Fibonacci) y se ajustan con el equipo en el Sprint Planning.
A4: Prioridad # | B4: ID | C4: Módulo / Épica | D4: Historia de usuario | E4: Criterio de aceptación | F4: Prioridad | G4: Objetivo vinculado | H4: Puntos de historia | I4: Sprint sugerido
A5: 1 | B5: PB-00 | C5: Organización del proyecto | D5: Como equipo de desarrollo, quiero organizar el proyecto (roles, tablero Trello, repositorio y prototipos de pantallas) para empezar a programar con un plan claro. | E5: El tablero Trello tiene el backlog cargado; cada integrante tiene un rol asignado; el repositorio está creado; los prototipos de las pantallas principales fueron revisados por la dueña del negocio. | F5: Alta | G5: Transversal | H5: 3 | I5: Sprint 1
A6: 2 | B6: PB-10 | C6: Seguridad | D6: Como administradora, quiero que los usuarios inicien sesión con roles (administrador, almacén) para proteger la información. | E6: Solo ingresa quien tiene usuario y contraseña válidos; con datos incorrectos se muestra un mensaje de error. El rol administrador accede a todas las opciones y crea usuarios; el rol almacén accede a productos, proveedores, movimientos, pedidos, tablero y notas de venta, pero no a reportes ni a la administración de usuarios (ver hoja Roles y Permisos). | F6: Alta | G6: Transversal | H6: 5 | I6: Sprint 2
A7: 3 | B7: PB-11 | C7: Gestión de proveedores | D7: Como encargado de almacén, quiero registrar proveedores (nombre, contacto, productos) para asociarlos a los pedidos. | E7: Los roles administrador y almacén pueden crear y editar un proveedor con nombre, contacto y productos que ofrece; al registrar un pedido se puede seleccionar un proveedor de la lista. | F7: Alta | G7: OE3 | H7: 3 | I7: Sprint 2
A8: 4 | B8: PB-01 | C8: Gestión de productos | D8: Como encargado de almacén, quiero registrar productos (nombre, código, categoría, precio, stock inicial) para tener un catálogo digital del inventario. | E8: Se puede crear, editar y desactivar un producto con nombre, código, categoría, precio y stock inicial; si el código ya existe, el sistema muestra un mensaje de error y no guarda; un producto desactivado no aparece al registrar entradas o salidas. | F8: Alta | G8: OE1 | H8: 5 | I8: Sprint 2
A9: 5 | B9: PB-02 | C9: Movimientos de stock | D9: Como encargado de almacén, quiero registrar las entradas de productos para que el stock se actualice automáticamente. | E9: Al guardar una entrada con cantidad mayor a 0, el stock del producto aumenta en esa cantidad; el movimiento queda registrado con fecha, hora y usuario responsable. | F9: Alta | G9: OE1 | H9: 5 | I9: Sprint 2
A10: 6 | B10: PB-03 | C10: Movimientos de stock | D10: Como encargado de almacén, quiero registrar las salidas de productos para que el stock se actualice automáticamente. | E10: Al guardar una salida, el stock disminuye en la cantidad indicada; si la cantidad es mayor al stock disponible, el sistema muestra un mensaje de error y no guarda la salida. | F10: Alta | G10: OE1 | H10: 5 | I10: Sprint 3
A11: 7 | B11: PB-04 | C11: Consulta de stock | D11: Como dueña del negocio, quiero consultar el stock actual de cada producto en tiempo real para conocer la cantidad real disponible. | E11: La lista de productos muestra el stock vigente de cada producto; después de guardar una entrada o salida, el nuevo stock se ve en la lista en menos de 2 segundos, sin recargar manualmente. | F11: Alta | G11: OE1 | H11: 3 | I11: Sprint 3
A12: 8 | B12: PB-05 | C12: Control de stock | D12: Como encargado de almacén, quiero definir un stock mínimo por producto para saber cuándo necesita reabastecerse. | E12: Cada producto tiene un campo de stock mínimo (número entero mayor o igual a 0) que se puede ver y editar; el sistema rechaza valores negativos o texto. | F12: Alta | G12: OE2 | H12: 2 | I12: Sprint 3
A13: 9 | B13: PB-06 | C13: Control de stock | D13: Como dueña del negocio, quiero recibir alertas de productos con stock bajo para abastecerme a tiempo. | E13: Los productos con stock actual menor o igual a su stock mínimo aparecen en una lista de alertas y se resaltan en rojo en la lista de productos; al superar el mínimo, dejan de aparecer en la lista de alertas. | F13: Alta | G13: OE2 | H13: 5 | I13: Sprint 3
A14: 10 | B14: PB-07 | C14: Gestión de pedidos | D14: Como encargado de almacén, quiero registrar pedidos de reabastecimiento con los productos y cantidades para controlar lo que se ha solicitado. | E14: El pedido se guarda con fecha, fecha estimada de llegada, proveedor, productos, cantidades (mayores a 0) y estado "Pendiente"; no se puede guardar un pedido sin proveedor o sin al menos un producto. | F14: Alta | G14: OE3 | H14: 8 | I14: Sprint 4
A15: 11 | B15: PB-08 | C15: Gestión de pedidos | D15: Como encargado de almacén, quiero ver el estado de cada pedido (Pendiente, En camino, Recibido) para hacer seguimiento. | E15: Cada pedido muestra su estado (Pendiente, En camino o Recibido) en la lista de pedidos; el encargado puede cambiar el estado y el nuevo estado se ve en la lista al guardar. | F15: Alta | G15: OE3 | H15: 5 | I15: Sprint 4
A16: 12 | B16: PB-09 | C16: Gestión de pedidos | D16: Como encargado de almacén, quiero registrar la recepción de los productos de un pedido para que el stock se actualice y se cierre el pedido. | E16: Al confirmar la recepción, se genera una entrada de stock por cada producto del pedido con la cantidad recibida y el pedido pasa a "Recibido"; un pedido ya recibido no se puede recibir de nuevo. | F16: Alta | G16: OE3 | H16: 5 | I16: Sprint 4
... A23: 19 | B23: PB-17 | C23: Reportes | D23: Como dueña del negocio, quiero exportar los reportes a Excel o PDF para guardarlos o compartirlos. | E23: Los botones "Exportar a Excel" y "Exportar a PDF" descargan un archivo con los mismos datos que muestra el reporte en pantalla. | F23: Baja | G23: Mejora | H23: 3 | I23: Sprint 5
G24: Total puntos | H24: =SUM(H5:H23) -> 86

Sheet Req. Funcionales
A1: REQUERIMIENTOS FUNCIONALES – Sistema de gestión de inventario
A2: Módulo, prioridad y sprint se leen automáticamente de la hoja Product Backlog.
A4: ID | B4: Módulo / Épica | C4: Requerimiento | D4: Historia relacionada | E4: Prioridad | F4: Sprint
A5: RF-01 | B5: =INDEX('Product Backlog'!$C$5:$C$23,MATCH(D5,'Product Backlog'!$B$5:$B$23,0)) -> Gestión de productos | C5: El sistema debe permitir crear, editar y desactivar productos con nombre, código, categoría, precio y stock inicial, y no permitir códigos repetidos. | D5: PB-01 | E5: =INDEX('Product Backlog'!$F$5:$F$23,MATCH(D5,'Product Backlog'!$B$5:$B$23,0)) -> Alta | F5: =INDEX('Product Backlog'!$I$5:$I$23,MATCH(D5,'Product Backlog'!$B$5:$B$23,0)) -> Sprint 2
A6: RF-02 | B6: =INDEX('Product Backlog'!$C$5:$C$23,MATCH(D6,'Product Backlog'!$B$5:$B$23,0)) -> Movimientos de stock | C6: El sistema debe registrar entradas de mercadería, aumentar el stock del producto y guardar fecha, hora y usuario responsable. | D6: PB-02 | E6: =INDEX('Product Backlog'!$F$5:$F$23,MATCH(D6,'Product Backlog'!$B$5:$B$23,0)) -> Alta | F6: =INDEX('Product Backlog'!$I$5:$I$23,MATCH(D6,'Product Backlog'!$B$5:$B$23,0)) -> Sprint 2
A7: RF-03 | B7: =INDEX('Product Backlog'!$C$5:$C$23,MATCH(D7,'Product Backlog'!$B$5:$B$23,0)) -> Movimientos de stock | C7: El sistema debe registrar salidas de mercadería, disminuir el stock y rechazar salidas mayores al stock disponible. | D7: PB-03 | E7: =INDEX('Product Backlog'!$F$5:$F$23,MATCH(D7,'Product Backlog'!$B$5:$B$23,0)) -> Alta | F7: =INDEX('Product Backlog'!$I$5:$I$23,MATCH(D7,'Product Backlog'!$B$5:$B$23,0)) -> Sprint 3
A8: RF-04 | B8: =INDEX('Product Backlog'!$C$5:$C$23,MATCH(D8,'Product Backlog'!$B$5:$B$23,0)) -> Consulta de stock | C8: El sistema debe mostrar el stock actual de cada producto y actualizarlo después de cada entrada o salida. | D8: PB-04 | E8: =INDEX('Product Backlog'!$F$5:$F$23,MATCH(D8,'Product Backlog'!$B$5:$B$23,0)) -> Alta | F8: =INDEX('Product Backlog'!$I$5:$I$23,MATCH(D8,'Product Backlog'!$B$5:$B$23,0)) -> Sprint 3
A9: RF-05 | B9: =INDEX('Product Backlog'!$C$5:$C$23,MATCH(D9,'Product Backlog'!$B$5:$B$23,0)) -> Control de stock | C9: El sistema debe permitir definir y editar un stock mínimo (entero mayor o igual a 0) por producto. | D9: PB-05 | E9: =INDEX('Product Backlog'!$F$5:$F$23,MATCH(D9,'Product Backlog'!$B$5:$B$23,0)) -> Alta | F9: =INDEX('Product Backlog'!$I$5:$I$23,MATCH(D9,'Product Backlog'!$B$5:$B$23,0)) -> Sprint 3
A10: RF-06 | B10: =INDEX('Product Backlog'!$C$5:$C$23,MATCH(D10,'Product Backlog'!$B$5:$B$23,0)) -> Control de stock | C10: El sistema debe mostrar una lista de alertas y resaltar los productos cuyo stock sea menor o igual al stock mínimo. | D10: PB-06 | E10: =INDEX('Product Backlog'!$F$5:$F$23,MATCH(D10,'Product Backlog'!$B$5:$B$23,0)) -> Alta | F10: =INDEX('Product Backlog'!$I$5:$I$23,MATCH(D10,'Product Backlog'!$B$5:$B$23,0)) -> Sprint 3
A11: RF-07 | B11: =INDEX('Product Backlog'!$C$5:$C$23,MATCH(D11,'Product Backlog'!$B$5:$B$23,0)) -> Gestión de pedidos | C11: El sistema debe registrar pedidos a proveedores con fecha, fecha estimada de llegada, proveedor, productos y cantidades. | D11: PB-07 | E11: =INDEX('Product Backlog'!$F$5:$F$23,MATCH(D11,'Product Backlog'!$B$5:$B$23,0)) -> Alta | F11: =INDEX('Product Backlog'!$I$5:$I$23,MATCH(D11,'Product Backlog'!$B$5:$B$23,0)) -> Sprint 4
A12: RF-08 | B12: =INDEX('Product Backlog'!$C$5:$C$23,MATCH(D12,'Product Backlog'!$B$5:$B$23,0)) -> Gestión de pedidos | C12: El sistema debe mostrar y permitir cambiar el estado de cada pedido (Pendiente, En camino, Recibido). | D12: PB-08 | E12: =INDEX('Product Backlog'!$F$5:$F$23,MATCH(D12,'Product Backlog'!$B$5:$B$23,0)) -> Alta | F12: =INDEX('Product Backlog'!$I$5:$I$23,MATCH(D12,'Product Backlog'!$B$5:$B$23,0)) -> Sprint 4
A13: RF-09 | B13: =INDEX('Product Backlog'!$C$5:$C$23,MATCH(D13,'Product Backlog'!$B$5:$B$23,0)) -> Gestión de pedidos | C13: El sistema debe permitir confirmar la recepción de un pedido y generar automáticamente las entradas de stock correspondientes. | D13: PB-09 | E13: =INDEX('Product Backlog'!$F$5:$F$23,MATCH(D13,'Product Backlog'!$B$5:$B$23,0)) -> Alta | F13: =INDEX('Product Backlog'!$I$5:$I$23,MATCH(D13,'Product Backlog'!$B$5:$B$23,0)) -> Sprint 4
A14: RF-10 | B14: =INDEX('Product Backlog'!$C$5:$C$23,MATCH(D14,'Product Backlog'!$B$5:$B$23,0)) -> Seguridad | C14: El sistema debe exigir usuario y contraseña para ingresar y limitar las opciones visibles según el rol (administrador o almacén), según la hoja Roles y Permisos. | D14: PB-10 | E14: =INDEX('Product Backlog'!$F$5:$F$23,MATCH(D14,'Product Backlog'!$B$5:$B$23,0)) -> Alta | F14: =INDEX('Product Backlog'!$I$5:$I$23,MATCH(D14,'Product Backlog'!$B$5:$B$23,0)) -> Sprint 2
A15: RF-11 | B15: =INDEX('Product Backlog'!$C$5:$C$23,MATCH(D15,'Product Backlog'!$B$5:$B$23,0)) -> Gestión de proveedores | C15: El sistema debe permitir a los roles administrador y almacén crear y editar proveedores (nombre, contacto, productos que ofrece) y seleccionarlos al registrar un pedido. | D15: PB-11 | E15: =INDEX('Product Backlog'!$F$5:$F$23,MATCH(D15,'Product Backlog'!$B$5:$B$23,0)) -> Alta | F15: =INDEX('Product Backlog'!$I$5:$I$23,MATCH(D15,'Product Backlog'!$B$5:$B$23,0)) -> Sprint 2
A16: RF-12 | B16: =INDEX('Product Backlog'!$C$5:$C$23,MATCH(D16,'Product Backlog'!$B$5:$B$23,0)) -> Movimientos de stock | C16: El sistema debe mostrar el historial de entradas y salidas, filtrable por producto y rango de fechas. | D16: PB-12 | E16: =INDEX('Product Backlog'!$F$5:$F$23,MATCH(D16,'Product Backlog'!$B$5:$B$23,0)) -> Media | F16: =INDEX('Product Backlog'!$I$5:$I$23,MATCH(D16,'Product Backlog'!$B$5:$B$23,0)) -> Sprint 3
... A22: RF-18 | B22: =INDEX('Product Backlog'!$C$5:$C$23,MATCH(D22,'Product Backlog'!$B$5:$B$23,0)) -> Notas de venta | C22: El sistema debe generar una nota de venta con número correlativo, fecha, cliente, detalle de productos y total al registrar una venta, descontar el stock y permitir imprimirla o descargarla en PDF. | D22: PB-18 | E22: =INDEX('Product Backlog'!$F$5:$F$23,MATCH(D22,'Product Backlog'!$B$5:$B$23,0)) -> Media | F22: =INDEX('Product Backlog'!$I$5:$I$23,MATCH(D22,'Product Backlog'!$B$5:$B$23,0)) -> Sprint 4

Sheet Req. No Funcionales
A1: REQUERIMIENTOS NO FUNCIONALES – Sistema de gestión de inventario
A2: Los valores numéricos son propuestas a confirmar con la dueña del negocio.
A4: ID | B4: Módulo / Épica | C4: Tipo de requerimiento | D4: Requerimiento | E4: Criterio medible | F4: Prioridad | G4: Historias relacionadas
A5: RNF-01 | B5: Consulta de stock | C5: Rendimiento | D5: Las consultas y búsquedas de productos deben responder rápido. | E5: Respuesta en menos de 2 segundos con hasta 1.000 productos registrados. | F5: Alta | G5: PB-04, PB-16
A6: RNF-02 | B6: Movimientos de stock | C6: Rendimiento | D6: El stock mostrado debe actualizarse tras registrar un movimiento. | E6: El nuevo stock se ve en la lista en menos de 2 segundos, sin recargar manualmente. | F6: Alta | G6: PB-02, PB-03, PB-04
A7: RNF-03 | B7: Seguridad | C7: Seguridad | D7: Las contraseñas no deben guardarse en texto plano. | E7: Contraseñas almacenadas con cifrado hash (por ejemplo, bcrypt). | F7: Alta | G7: PB-10
A8: RNF-04 | B8: Seguridad | C8: Seguridad | D8: El acceso a las funciones debe depender del rol del usuario. | E8: El rol almacén no puede abrir reportes ni la administración de usuarios; se prueba con ambos roles. | F8: Alta | G8: PB-10
A9: RNF-05 | B9: Seguridad | C9: Seguridad | D9: La sesión debe cerrarse por inactividad. | E9: Cierre automático tras 15 minutos sin actividad. | F9: Media | G9: PB-10
A10: RNF-06 | B10: Movimientos de stock | C10: Usabilidad | D10: Registrar una entrada o salida debe ser sencillo para personal sin experiencia técnica. | E10: Un usuario nuevo registra una salida en menos de 1 minuto tras una capacitación de 15 minutos. | F10: Alta | G10: PB-02, PB-03
A11: RNF-07 | B11: Todos los módulos | C11: Usabilidad | D11: La interfaz y los mensajes de error deben estar en español y ser claros. | E11: Todo mensaje de error indica qué pasó y cómo corregirlo. | F11: Media | G11: Todas
A12: RNF-08 | B12: Todos los módulos | C12: Compatibilidad | D12: El sistema debe funcionar en los navegadores más usados. | E12: Funciona en las últimas versiones de Chrome, Edge y Firefox. | F12: Alta | G12: Todas
A13: RNF-09 | B13: Todos los módulos | C13: Compatibilidad | D13: La interfaz debe adaptarse a distintos tamaños de pantalla. | E13: Se usa sin desplazamiento horizontal en PC (1366 px) y tablet (768 px). | F13: Media | G13: Todas
A14: RNF-10 | B14: Todos los módulos | C14: Disponibilidad | D14: El sistema debe estar disponible en el horario de atención del negocio. | E14: Disponibilidad mínima del 95% en el horario de atención. | F14: Media | G14: Todas
A15: RNF-11 | B15: Todos los módulos | C15: Confiabilidad | D15: Los datos deben poder recuperarse ante una falla. | E15: Copia de respaldo automática de la base de datos cada día. | F15: Alta | G15: Todas
... A18: RNF-14 | B18: Organización del proyecto | C18: Mantenibilidad | D18: El código debe estar organizado y versionado. | E18: Código en repositorio con control de versiones y un README con instrucciones de instalación. | F18: Media | G18: PB-00

Sheet Roles y Permisos
A1: ROLES Y PERMISOS – Sistema de gestión de inventario
A2: Define qué puede hacer cada rol (PB-10). El módulo se lee de la hoja Product Backlog.
A4: Módulo / Épica | B4: Función | C4: Historia relacionada | D4: Administrador | E4: Almacén
A5: =INDEX('Product Backlog'!$C$5:$C$23,MATCH(C5,'Product Backlog'!$B$5:$B$23,0)) -> Seguridad | B5: Iniciar sesión | C5: PB-10 | D5: Sí | E5: Sí
A6: =INDEX('Product Backlog'!$C$5:$C$23,MATCH(C6,'Product Backlog'!$B$5:$B$23,0)) -> Seguridad | B6: Crear usuarios y asignar roles | C6: PB-10 | D6: Sí | E6: No
A7: =INDEX('Product Backlog'!$C$5:$C$23,MATCH(C7,'Product Backlog'!$B$5:$B$23,0)) -> Gestión de productos | B7: Registrar, editar y desactivar productos | C7: PB-01 | D7: Sí | E7: Sí
A8: =INDEX('Product Backlog'!$C$5:$C$23,MATCH(C8,'Product Backlog'!$B$5:$B$23,0)) -> Gestión de productos | B8: Buscar y filtrar productos | C8: PB-16 | D8: Sí | E8: Sí
A9: =INDEX('Product Backlog'!$C$5:$C$23,MATCH(C9,'Product Backlog'!$B$5:$B$23,0)) -> Movimientos de stock | B9: Registrar entradas de productos | C9: PB-02 | D9: Sí | E9: Sí
A10: =INDEX('Product Backlog'!$C$5:$C$23,MATCH(C10,'Product Backlog'!$B$5:$B$23,0)) -> Movimientos de stock | B10: Registrar salidas de productos | C10: PB-03 | D10: Sí | E10: Sí
A11: =INDEX('Product Backlog'!$C$5:$C$23,MATCH(C11,'Product Backlog'!$B$5:$B$23,0)) -> Consulta de stock | B11: Consultar el stock actual | C11: PB-04 | D11: Sí | E11: Sí
A12: =INDEX('Product Backlog'!$C$5:$C$23,MATCH(C12,'Product Backlog'!$B$5:$B$23,0)) -> Control de stock | B12: Definir el stock mínimo | C12: PB-05 | D12: Sí | E12: Sí
A13: =INDEX('Product Backlog'!$C$5:$C$23,MATCH(C13,'Product Backlog'!$B$5:$B$23,0)) -> Control de stock | B13: Ver alertas de stock bajo | C13: PB-06 | D13: Sí | E13: Sí
A14: =INDEX('Product Backlog'!$C$5:$C$23,MATCH(C14,'Product Backlog'!$B$5:$B$23,0)) -> Movimientos de stock | B14: Ver el historial de movimientos (kardex) | C14: PB-12 | D14: Sí | E14: Sí
A15: =INDEX('Product Backlog'!$C$5:$C$23,MATCH(C15,'Product Backlog'!$B$5:$B$23,0)) -> Gestión de proveedores | B15: Registrar y editar proveedores | C15: PB-11 | D15: Sí | E15: Sí
A16: =INDEX('Product Backlog'!$C$5:$C$23,MATCH(C16,'Product Backlog'!$B$5:$B$23,0)) -> Gestión de pedidos | B16: Registrar pedidos de reabastecimiento | C16: PB-07 | D16: Sí | E16: Sí
... A23: =INDEX('Product Backlog'!$C$5:$C$23,MATCH(C23,'Product Backlog'!$B$5:$B$23,0)) -> Reportes | B23: Exportar reportes a Excel o PDF | C23: PB-17 | D23: Sí | E23: No
A25: Descripción de los roles
A26: Administrador | B26: Dueña del negocio. Accede a todas las funciones, crea usuarios y consulta reportes.
A27: Almacén | B27: Encargado de almacén. Maneja productos, proveedores, movimientos, pedidos, tablero y notas de venta. No ve reportes ni administra usuarios.

Sheet Campos de las Tablas
A1: CAMPOS DE LAS TABLAS – Diccionario de datos del sistema de inventario
A2: Basado en el modelo de datos del documento (sección 3.3). PK = clave primaria, FK = clave foránea, UQ = valor único. Origen: Diagrama = está en el modelo; Sugerido = falta en el diagrama y lo piden las historias; Revisar = confirmar con el equipo.
A4: Tabla | B4: Campo | C4: Tipo de dato | D4: Clave | E4: Obligatorio | F4: Descripción / regla | G4: Historia relacionada | H4: Origen
A5: USUARIOS | B5: id_usuario | C5: INT | D5: PK | E5: Sí | F5: Identificador autogenerado. | G5: PB-10 | H5: Diagrama
B6: nombre | C6: VARCHAR(50) | E6: Sí | F6: Nombres del usuario. | G6: PB-10 | H6: Diagrama
B7: apellido | C7: VARCHAR(50) | E7: Sí | F7: Apellidos del usuario. | G7: PB-10 | H7: Diagrama
B8: correo | C8: VARCHAR(100) | D8: UQ | E8: Sí | F8: Se usa para iniciar sesión; no se repite. | G8: PB-10 | H8: Diagrama
B9: contraseña | C9: VARCHAR(255) | E9: Sí | F9: Se guarda cifrada con hash, nunca en texto plano (RNF-03). | G9: PB-10 | H9: Diagrama
B10: rol | C10: VARCHAR(15) | E10: Sí | F10: Administrador o Almacén (ver hoja Roles y Permisos). | G10: PB-10 | H10: Diagrama
B11: estado | C11: VARCHAR(10) | E11: Sí | F11: Activo o Inactivo; un usuario inactivo no puede ingresar. | G11: PB-10 | H11: Diagrama
A12: PRODUCTOS | B12: id_producto | C12: INT | D12: PK | E12: Sí | F12: Identificador autogenerado. | G12: PB-01 | H12: Diagrama
B13: codigo | C13: VARCHAR(20) | D13: UQ | E13: Sí | F13: Código del producto; no se permiten repetidos. | G13: PB-01 | H13: Diagrama
B14: nombre | C14: VARCHAR(100) | E14: Sí | F14: Nombre del producto. | G14: PB-01 | H14: Diagrama
B15: descripcion | C15: VARCHAR(255) | E15: No | F15: Detalle opcional del producto. | G15: PB-01 | H15: Diagrama
B16: categoria | C16: VARCHAR(50) | E16: Sí | F16: Categoría; se usa para buscar y filtrar. | G16: PB-01, PB-16 | H16: Diagrama
B17: precio | C17: DECIMAL(10,2) | E17: Sí | F17: Precio de venta unitario; mayor o igual a 0. | G17: PB-01 | H17: Diagrama
B18: stock | C18: INT | E18: Sí | F18: Cantidad disponible; nunca negativa. Empieza con el stock inicial. | G18: PB-01, PB-04 | H18: Diagrama
B19: stock_minimo | C19: INT | E19: Sí | F19: Cantidad mínima antes de alertar; entero mayor o igual a 0. | G19: PB-05, PB-06 | H19: Diagrama
B20: id_proveedor | C20: INT | D20: FK → PROVEEDORES.id_proveedor | E20: No | F20: Proveedor que abastece el producto. | G20: PB-11 | H20: Diagrama
B21: estado | C21: VARCHAR(10) | E21: Sí | F21: Activo o Inactivo. Falta en el diagrama: PB-01 pide desactivar productos. | G21: PB-01 | H21: Sugerido
A22: PROVEEDORES | B22: id_proveedor | C22: INT | D22: PK | E22: Sí | F22: Identificador autogenerado. | G22: PB-11 | H22: Diagrama
B23: nombre | C23: VARCHAR(100) | E23: Sí | F23: Nombre o razón social. | G23: PB-11 | H23: Diagrama
B24: ruc | C24: CHAR(11) | D24: UQ | E24: Sí | F24: RUC del proveedor; 11 dígitos, no se repite. | G24: PB-11 | H24: Diagrama
B25: telefono | C25: VARCHAR(15) | E25: Sí | F25: Teléfono de contacto. | G25: PB-11 | H25: Diagrama
B26: correo | C26: VARCHAR(100) | E26: No | F26: Correo de contacto. | G26: PB-11 | H26: Diagrama
B27: direccion | C27: VARCHAR(150) | E27: No | F27: Dirección del proveedor. | G27: PB-11 | H27: Diagrama
B28: estado | C28: VARCHAR(10) | E28: Sí | F28: Activo o Inactivo; solo los activos se eligen en pedidos. | G28: PB-11 | H28: Diagrama
A29: PEDIDOS | B29: id_pedido | C29: INT | D29: PK | E29: Sí | F29: Identificador autogenerado. En el diagrama aparece como id_pedidos; conviene unificar con DETALLE_PEDIDO. | G29: PB-07 | H29: Revisar
B30: fecha_pedido | C30: DATE | E30: Sí | F30: Fecha en que se registra el pedido. | G30: PB-07 | H30: Diagrama
B31: estado | C31: VARCHAR(10) | E31: Sí | F31: Pendiente, En camino o Recibido. "Atrasado" no se guarda: se calcula con la fecha estimada. | G31: PB-08, PB-13 | H31: Diagrama
B32: fecha_estimada_entrega | C32: DATE | E32: Sí | F32: Fecha prevista de llegada; sirve para detectar pedidos atrasados. | G32: PB-07, PB-13 | H32: Diagrama
B33: id_proveedor | C33: INT | D33: FK → PROVEEDORES.id_proveedor | E33: Sí | F33: Proveedor al que se hace el pedido. | G33: PB-07, PB-11 | H33: Diagrama
B34: id_usuario | C34: INT | D34: FK → USUARIOS.id_usuario | E34: Sí | F34: Usuario que registró el pedido. | G34: PB-07 | H34: Diagrama
A35: DETALLE_PEDIDO | B35: id_detalle | C35: INT | D35: PK | E35: Sí | F35: Identificador autogenerado. | G35: PB-07 | H35: Diagrama
B36: id_pedido | C36: INT | D36: FK → PEDIDOS.id_pedido | E36: Sí | F36: Pedido al que pertenece la línea. | G36: PB-07 | H36: Diagrama
B37: id_producto | C37: INT | D37: FK → PRODUCTOS.id_producto | E37: Sí | F37: Producto solicitado. | G37: PB-07 | H37: Diagrama
B38: cantidad | C38: INT | E38: Sí | F38: Cantidad solicitada, mayor a 0; es la que se ingresa al stock al recibir el pedido. | G38: PB-07, PB-09 | H38: Diagrama
B39: precio | C39: DECIMAL(10,2) | E39: Sí | F39: Precio unitario del producto en el pedido. | G39: PB-07 | H39: Diagrama
A40: MOVIMIENTOS | B40: id_movimiento | C40: INT | D40: PK | E40: Sí | F40: Identificador autogenerado. | G40: PB-02 | H40: Diagrama
B41: id_producto | C41: INT | D41: FK → PRODUCTOS.id_producto | E41: Sí | F41: Producto afectado. | G41: PB-02, PB-03 | H41: Diagrama
...
